Workbook

Sheet 2006
A1: TT | B1: TÊN SÁCH | C1: TÁC GIẢ | D1: PHƯƠNG THỨC | E1: Lần XB | F1: SỐ LƯỢNG IN | G1: TRANG | H1: KHỔ SÁCH | I1: GIÁ BÌA | J1: Ruột | K1: Bìa | L1: Đủ Ruột + bìa | M1: Ghi chú
A2: 1 | B2: Lịch sử Chính phủ Việt Nam- T1 (1945-1955) | C2: Ban chỉ đạo biên soạn lịch sử Chính phủ Việt Nam | D2: TW ĐẶT HÀNG | F2: 1040 | G2: 454 | H2: 16x24 | I2: Không giá | J2: ko có | K2: ko có
A3: 2 | B3: Văn kiện Đảng toàn tập- Tập43 (1982) | C3: ĐCSVN | D3: TW ĐẶT HÀNG | F3: 6000 | G3: 812 | H3: 15x22 | I3: Không giá | J3: ko có | K3: ko có
A4: 3 | B4: Tệ quan liêu, lãng phí và một số giải pháp phòng, chống | C4: Ban chỉ đạo TW6(2) | D4: TW ĐẶT HÀNG | F4: 3500 | G4: 666 | H4: 15x22 | I4: 30000 | J4: ko có | K4: ko có
A5: 4 | B5: Đổi mới công tác kiểm tra, kỷ luật nhằm nâng cao sức chiến đấu của Đảng trong giai đoạn cách mạng mới | C5: GS,TS.Nguyễn Thị Doan | D5: TW ĐẶT HÀNG | F5: 1200 | G5: 316 | H5: 14,5x20,5 | I5: 30000 | J5: ko có | K5: ko có
A6: 5 | B6: Đổi mới sâu rộng, phát triển đát nước nhanh và bền vững, tiến cùng thời đại - T1 | C6: Phan Văn Khải | D6: TW ĐẶT HÀNG | F6: 2000 | G6: 536 | H6: 15x22 | I6: 45000 | J6: ko có | K6: ko có
A7: 6 | B7: Hồ Chí Minh- Biên niên tiểu sử Tập 1(1890-1929) | C7: Học viện CTQGHCM | D7: TW ĐẶT HÀNG | F7: 2000 | G7: 456 | H7: 14,5x20,5 | I7: 50000 | J7: ko có | K7: ko có
A8: 7 | B8: Văn kiện Đảng toàn tập- Tập46 (1985) | C8: ĐCSVN | D8: TW ĐẶT HÀNG | F8: 6000 | G8: 422 | H8: 15x22 | I8: Không giá | J8: ko có | K8: ko có
A9: 8 | B9: Đổi mới sâu rộng, phát triển đát nước nhanh và bền vững, tiến cùng thời đại - T2 | C9: Phan Văn Khải | D9: TW ĐẶT HÀNG | F9: 2000 | G9: 528 | H9: 15x22 | I9: 45000 | J9: ko có | K9: ko có
A10: 9 | B10: Văn kiện Đảng toàn tập- Tập45 (1984) | C10: ĐCSVN | D10: TW ĐẶT HÀNG | F10: 6000 | G10: 510 | H10: 15x22 | I10: Không giá | J10: ko có | K10: ko có
A11: 10 | B11: Kết quả Đại hội đại biểu toàn quốc lần thứ X Đảng Cộng sản Việt Nam | C11: Văn phòng TWĐCSVN | D11: TW ĐẶT HÀNG | F11: 5000 | G11: 118 | H11: 13x19 | I11: 5000 | J11: ko có | K11: ko có
A12: 11 | B12: Văn kiện Đảng toàn tập- Tập44 (1983) | C12: ĐCSVN | D12: TW ĐẶT HÀNG | F12: 6000 | G12: 480 | H12: 15x22 | I12: Không giá | J12: ko có | K12: ko có
A13: 12 | B13: Hồ Chí Minh- Biên niên tiểu sử Tập 2(1930-1945) | C13: Học viện CTQGHCM | D13: TW ĐẶT HÀNG | F13: 2000 | G13: 348 | H13: 14,5x20,5 | I13: 40000 | J13: ko có | K13: ko có
A14: 13 | B14: Đổi mới và phát triển ở Việt Nam- một số vấn đề lý luận và thực tiễn | C14: GS,TS.Nguyễn Phú Trọng | D14: TW ĐẶT HÀNG | F14: 1000 | G14: 484 | H14: 15x22 | I14: 60000 | J14: ko có | K14: ko có
A15: 14 | B15: C.Mác và Ph.ĂngGhen tuyển tập Tập 5 | D15: TW ĐẶT HÀNG | F15: 1040 | G15: 830 | H15: 15x22 | I15: 93000 | J15: ko có | K15: ko có
A16: 15 | B16: C.Mác và Ph.ĂngGhen tuyển tập Tập 6 | D16: TW ĐẶT HÀNG | F16: 1040 | G16: 846 | H16: 15x22 | I16: 95000 | J16: ko có | K16: ko có
A17: 16 | B17: Văn kiện Đại hội đại biểu toàn quốc lần thứ X | C17: ĐCSVN | D17: TW ĐẶT HÀNG | F17: 130000 | G17: 376 | H17: 13x19 | I17: Không giá | J17: ko có | K17: ko có
A18: 17 | B18: Văn kiện Đảng toàn tập- Tập47 (1986) | C18: ĐCSVN | D18: TW ĐẶT HÀNG | F18: 6000 | G18: 656 | H18: 15x22 | I18: Không giá | J18: ko có | K18: ko có
A19: 18 | B19: Việt Nam bước khởi động 5 năm đầu thế kỷ thắng lợi | C19: Trần Đức Lương | D19: TW ĐẶT HÀNG | F19: 1000 | G19: 758 | H19: 16x24 | I19: 115000 | J19: ko có | K19: ko có
A20: 19 | B20: Tham luận tại Đại hội đại biểu toàn quốc lần thứ X | C20: ĐCSVN | D20: TW ĐẶT HÀNG | F20: 5000 | G20: 444 | H20: 16x24 | I20: Không giá | J20: ko có | K20: ko có
A21: 20 | B21: Chính quyền địa phương trong nhà nước pháp quyền XHCN của dân, do dân, vì dân | C21: PGS,TS.Lê Minh Thông | D21: TW ĐẶT HÀNG | F21: 1040 | G21: 414 | H21: 19x27 | I21: 145000 | J21: ko có | K21: ko có
A22: 21 | B22: Sở hữu tư nhân và kinh tế tư nhân trong nền kinh tế thị trường định hướng XHCN ở Việt Nam | C22: GS,TS.Nguyễn Thanh Tuyền | D22: TW ĐẶT HÀNG | F22: 500 | G22: 362 | H22: 14,5x20,5 | I22: 35000 | J22: ko có | K22: ko có
A23: 22 | B23: Đồng chí Phạm Văn Xô- Người cán bộ lão thành nhân hậu, giản dị | D23: TW ĐẶT HÀNG | F23: 1000 | G23: 416 | H23: 15x22 | I23: 42000 | J23: ko có | K23: ko có
A24: 23 | B24: Văn kiện Đại hội đại biểu toàn quốc lần thứ X | C24: ĐCSVN | D24: TW ĐẶT HÀNG | F24: 10000 | G24: 376 | H24: 13x19 | I24: 20000 | J24: ko có | K24: ko có
A25: 24 | B25: Hà Huy Tập- Ngưòi cộng sản kiên trung,nhà lý luận xuất sắc | D25: TW ĐẶT HÀNG | F25: 1000 | G25: 760 | H25: 16x24 | I25: Không giá | J25: ko có | K25: ko có
A26: 25 | B26: Lịch sử Chính phủ Việt Nam- T2 (1955-1976) | C26: Ban chỉ đạo biên soạn lịch sử Chính phủ Việt Nam | D26: TW ĐẶT HÀNG | F26: 1000 | G26: 506 | H26: 16x24 | I26: Không giá | J26: ko có | K26: ko có
A27: 26 | B27: Lịch sử Chính phủ Việt Nam- T3 (1976-2005) | C27: Ban chỉ đạo biên soạn lịch sử Chính phủ Việt Nam | D27: TW ĐẶT HÀNG | F27: 1000 | G27: 592 | H27: 16x24 | I27: Không giá | J27: ko có | K27: ko có
A28: 27 | B28: Hồ Chí Minh- biên niên tiểu sử tập4 (1946-1950) | C28: Viện HCM | D28: TW ĐẶT HÀNG | F28: 2000 | G28: 562 | H28: 14,5x20,5 | I28: 60000 | J28: ko có | K28: ko có
A29: 28 | B29: Văn kiện Đảng Toàn tập Tập 48(1987) | C29: ĐCSVN | D29: TW ĐẶT HÀNG | F29: 6000 | G29: 650 | H29: 15x22 | I29: Không giá | J29: ko có | K29: ko có
A30: 29 | B30: Thể chế kinh tế thị trường định hướng XHCN ở Việt Nam | C30: PGS,TS.Hà Huy Bảo | D30: TW ĐẶT HÀNG | F30: 500 | G30: 380 | H30: 14,5x20,5 | I30: 36000 | J30: ko có | K30: ko có
A31: 30 | B31: Nông nghiệp nông thôn Việt Nam 20 năm đổi mới và phát triển | C31: Đặng Kim Sơn | D31: TW ĐẶT HÀNG | F31: 500 | G31: 244 | H31: 16x24 | I31: 32000 | J31: ko có | K31: ko có
A32: 31 | B32: Ngoại giao Việt Nam - phương sách và nghệ thuật đàm phán | C32: Nguyễn Khắc Huỳnh | D32: TW ĐẶT HÀNG | F32: 500 | G32: 396 | H32: 14,5x20,5 | I32: 37000 | J32: ko có | K32: ko có
A33: 32 | B33: Hồ Chí Minh- Biên niên tiểu sử tập 3 (1945-1946) | C33: Học viện CTQGHCM | D33: TW ĐẶT HÀNG | F33: 2000 | G33: 468 | H33: 14,5x20,5 | I33: 50000 | J33: ko có | K33: ko có
A34: 33 | B34: Đề cương bài giảng xử lý tình huống chính trị (cao cấp LLCT) | C34: Học viện CTQGHCM | D34: QUẢN LÝ PHÍ | F34: 1000 | G34: 116 | H34: 13x19 | I34: 13000 | J34: ko có | K34: ko có
A35: 34 | B35: Lịch sử Đảng bộ tỉnh Sơn La Tập III (1976-2000) | C35: BCHĐB Sơn La | D35: QUẢN LÝ PHÍ | F35: 3500 | G35: 252 | H35: 13x19 | I35: Không giá | J35: ko có | K35: ko có
A36: 35 | B36: Tìm hiểu luật bảo vệ, chăm sóc và giáo dục trẻ em năm 2004 | C36: Lg. Nguyễn Ngọc Dũng | D36: QUẢN LÝ PHÍ | F36: 1000 | G36: 48 | H36: 14,5x20,5 | I36: 6000 | J36: ko có | K36: ko có
A37: 36 | B37: Tìm hiểu luật thi đua, khen thưởng ( đã được sửa đổi ,bổ sung năm 2005) | C37: Lg. Nguyễn Ngọc Dũng | D37: QUẢN LÝ PHÍ | F37: 1000 | G37: 64 | H37: 14,5x20,5 | I37: 8000 | J37: ko có | K37: ko có
A38: 37 | B38: Tìm hiểu luật đường sắt | C38: Lg. Nguyễn Ngọc Dũng | D38: QUẢN LÝ PHÍ | F38: 1000 | G38: 96 | H38: 14,5x20,5 | I38: 12000 | J38: ko có | K38: ko có
A39: 38 | B39: Tìm hiểu luật các tổ chức tín dụng | C39: Lg. Nguyễn Ngọc Dũng | D39: QUẢN LÝ PHÍ | F39: 1000 | G39: 72 | H39: 14,5x20,5 | I39: 9000 | J39: ko có | K39: ko có
A40: 39 | B40: Tìm hiểu luật điện lực | C40: Lg. Nguyễn Văn Thung | D40: QUẢN LÝ PHÍ | F40: 1000 | G40: 72 | H40: 14,5x20,5 | I40: 9000 | J40: ko có | K40: ko có
...

Sheet 2007
A1: TT | B1: Tên sách | C1: Tác giả | D1: Phương thức | E1: Lần xuất bản | F1: Số lượng in | G1: Trang | H1: Khổ | I1: Giá bìa | J1: Ban BT | K1: QĐXB | L1: Nơi in | M1: Ruột | N1: Bìa
A2: 1 | B2: Quy định mới về xử lý trách nhiệm vật chất đối với cán bộ công chức | C2: QH | D2: CQ | E2: 1 | F2: 1000 | G2: 72 | H2: 13x19 | I2: 8000 | J2: Pháp luật | K2: 39085 | L2: CTQG | M2: Có | N2: Ko có | O2: file word
A3: 2 | B3: Chuyện nhà- Chuyện nước | C3: Hữu Thọ | D3: CQ | E3: 1 | F3: 1000 | G3: 260 | H3: 13x19 | I3: 22000 | J3: Đảng | K3: 39085 | L3: CTQG | M3: Ko có | N3: Ko có
A4: 3 | B4: Các quy định pháp luật về tăng cường quản lý thu chi ngân sách nhà nước | C4: QH | D4: CQ | E4: 1 | F4: 700 | G4: 320 | H4: 13x19 | I4: 27000 | J4: Pháp luật | K4: 39085 | L4: CTQG | M4: Ko có | N4: Ko có
A5: 4 | B5: Văn bản hướng dẫn thi hành Bộ luật hàng hải Việt Nam năm 2005 | C5: QH | D5: CQ | E5: 1 | F5: 500 | G5: 376 | H5: 13x19 | I5: 31000 | J5: Pháp luật | K5: 39085 | L5: CTQG | M5: Ko có | N5: Ko có
A6: 5 | B6: Giáo trình lịch sử kinh tế quốc dân | C6: PGS,TS.Vũ Văn Phúc | D6: CQ | E6: 1 | F6: 700 | G6: 468 | H6: 14,5x20,5 | I6: 43000 | J6: Kinh tế | K6: 39085 | L6: Nhà in Hà Nội | M6: Có | N6: không | O6: file word
A7: 6 | B7: Bộ luật dân sự năm 2005 và văn bản hướng dẫn thi hành | C7: QH | D7: CQ | E7: 1 | F7: 1000 | G7: 504 | H7: 19x27 | I7: 87000 | J7: Pháp luật | K7: 39085 | L7: CTQG | M7: Ko có | N7: Ko có
A8: 7 | B8: Lịch sử Đảng bộ và nhân dân thị trấn Hưng Hà (1930-2005 ) | C8: BCHĐB Hưng Hà | D8: LKTG | E8: 1 | F8: 700 | G8: 296 | H8: 13x19 | I8: Không giá | J8: Đảng | K8: 39085 | L8: Công ty in Giao thông | M8: Ko có | N8: Ko có
A9: 8 | B9: Phạm Văn Đồng và ngoại giao Việt Nam | C9: Bộ Ngoại giao | D9: LKTG | E9: 1 | F9: 1200 | G9: 768 | H9: 16x24 | I9: Không giá | J9: Quốc tế | K9: 39085 | L9: Công ty in Nam Thanh | M9: Ko có | N9: Ko có
A10: 9 | B10: Lôgích chính trị Mỹ | C10: Samuel Kernell Gary C. Jacob | D10: LKTG | E10: 1 | F10: 1000 | G10: 718 | H10: 19x27 | I10: Không giá | J10: Quốc tế | K10: 39085 | L10: Nhà in Hà Nội | M10: Ko có | N10: Ko có
A11: 10 | B11: Phát triển con người ở Việt Nam 1999-2004. Những thay đổi và xu hướng chủ yếu | C11: Viện KHXH Việt Nam | D11: LKTG | E11: 1 | F11: 2040 | G11: 106 | H11: 21x28 | I11: Không giá | J11: TT In | K11: 39085 | L11: Văn hóa phẩm | M11: Ko có | N11: Ko có
A12: 11 | B12: Bác Hồ ở Tân Trào | D12: QLP | E12: TB | F12: 2000 | G12: 156 | H12: 13x19 | I12: 15000 | J12: Đảng | K12: 39085 | L12: Tiến bộ | M12: Ko có | N12: Ko có
A13: 12 | B13: Quản lý đầu tư và thương mại toàn cầu. Các kỹ năng thiết yếu để thành công trong nền kinh tế toàn cầu WTO | C13: MiGuel Pardo De Zela | D13: QLP | E13: 1 | F13: 3040 | G13: 218 | H13: 19x27 | I13: 152000 | J13: Lý luận | K13: 39085 | L13: Tiến bộ | M13: Ko có | N13: Ko có
A14: 13 | B14: Thấm nhuần tư tưởng đạo đức Hồ Chí Minh | C14: TS.Phạm Văn Khánh | D14: CQ | E14: 1 | F14: 500 | G14: 176 | H14: 13x19 | I14: 19000 | J14: Đảng | K14: 39093 | L14: CTQG | M14: Ko có | N14: Ko có
A15: 14 | B15: Văn bản pháp luật về thanh tra, kiểm tra và xử lý vi phạm hành chính trong lĩnh vực kế hoạch đầu tư | C15: QH | D15: CQ | E15: 1 | F15: 700 | G15: 324 | H15: 13x19 | I15: 32000 | J15: Pháp luật | K15: 39093 | L15: CTQG | M15: Ko có | N15: Ko có
A16: 15 | B16: Luật người Việt Nam đi làm việc ở nước ngài theo hợp đồng năm 2006 và văn bản hướng dẫn thi hành | C16: QH | D16: CQ | E16: 1 | F16: 550 | G16: 228 | H16: 13x19 | I16: 24000 | J16: Pháp luật | K16: 39093 | L16: CTQG | M16: Ko có | N16: Ko có
A17: 16 | B17: Quy điịnh mới về bảo vệ, chăm sóc và giáo dục trẻ em | C17: QH | D17: CQ | E17: 1 | F17: 600 | G17: 172 | H17: 13x19 | I17: 18000 | J17: Pháp luật | K17: 39093 | L17: CTQG | M17: Ko có | N17: Ko có
A18: 17 | B18: Quy định về công tác quy hoạch kế hoạch phát triển kinh tế-xã hội | C18: QH | D18: CQ | E18: 1 | F18: 500 | G18: 288 | H18: 13x19 | I18: 29000 | J18: Pháp luật | K18: 39093 | L18: CTQG | M18: Ko có | N18: Ko có
A19: 18 | B19: Pháp lệnh dân quân tự vệ năm 2004 và văn bản hướng dẫn thi hành | C19: QH | D19: CQ | E19: 1 | F19: 1000 | G19: 184 | H19: 13x19 | I19: 20000 | J19: Pháp luật | K19: 39093 | L19: CTQG | M19: Ko có | N19: Ko có
A20: 19 | B20: Kiểm soát tập trung kinh tế Kinh nghiệm quốc tế và thực tiễn tại Việt Nam | C20: Bộ Công thương | D20: LKTG | E20: 1 | F20: 700 | G20: 312 | H20: 14,5x20,5 | I20: Không giá | J20: Ban Nghiên cứu KHXB | K20: 39093 | L20: CTQG | M20: Có | N20: file word
A21: 20 | B21: Quy định mới về phòng chống thiên tai | C21: QH | D21: CQ | E21: 1 | F21: 700 | G21: 236 | H21: 13x19 | I21: 20000 | J21: Pháp luật | K21: 19/1/2007 | L21: CTQG | M21: Ko có | N21: Ko có
A22: 21 | B22: Quy định mới về quản lý công sở và tiêu chuẩn, định mức trụ sở-trang thiết bị, phương tiện làm việc của cơ quan-cán bộ công chức viên chức nhà nước | C22: QH | D22: CQ | E22: 1 | F22: 1000 | G22: 120 | H22: 13x19 | I22: 11000 | J22: Pháp luật | K22: 19/1/2007 | L22: CTQG | M22: Ko có | N22: Ko có
A23: 22 | B23: Quy định mới hướng dẫn quy chế vay, trả nợ nước ngoài và quản lý, sử dụng nguồn hỗ trợ phát triển chính thức (ODA) | C23: QH | D23: CQ | E23: 1 | F23: 600 | G23: 192 | H23: 13x19 | I23: 17000 | J23: Pháp luật | K23: 19/1/2007 | L23: CTQG | M23: Ko có | N23: Ko có
A24: 23 | B24: Các quy định hướng dẫn thi hành việc chuyển hợp đồng thuê đất, cấp giấy chứng nhận quyền sử dụng đất khi chuyển công ty nhà nước thành công ty cổ phần | C24: QH | D24: CQ | E24: 1 | F24: 700 | G24: 292 | H24: 13x19 | I24: 25000 | J24: Pháp luật | K24: 19/1/2007 | L24: CTQG | M24: Ko có | N24: Ko có
A25: 24 | B25: Quy định mới về tổ chức và hoạt động của lực lượng kiểm lâm | C25: QH | D25: CQ | E25: 1 | F25: 1000 | G25: 124 | H25: 13x19 | I25: 11000 | J25: Pháp luật | K25: 19/1/2007 | L25: CTQG | M25: Ko có | N25: Ko có
A26: 25 | B26: Luật bảo hiểm xã hội và các văn bản có liên quan | C26: QH | D26: CQ | E26: 1 | F26: 2000 | G26: 116 | H26: 14,5x20,5 | I26: 13000 | J26: Quốc tế | K26: 19/1/2007 | L26: XN In và Văn hóa phẩm Bến Thành | M26: Ko có | N26: Ko có
A27: 26 | B27: Những vấn đề toàn cầu hóa trong hai thập niên đầu thế kỷ XXI | C27: GS,TS.Nguyễn Trọng Chuẩn | D27: LK 1phần | E27: 1 | F27: 580 | G27: 440 | H27: 14,5x20,5 | I27: 44000 | J27: Kinh điển | K27: 19/1/2007 | L27: CTQG | M27: Ko có | N27: Ko có
A28: 27 | B28: Lịch sử chính quyền Nhà nước Việt Nam | C28: TS.Nguyễn Vũ Tiến | D28: LKTG | E28: 1 | F28: 740 | G28: 236 | H28: 13x19 | I28: 23000 | J28: Giáo khoa | K28: 19/1/2007 | L28: CTQG | M28: Ko có | N28: Ko có
A29: 28 | B29: Phát triển công nghiệp chế biến nông sản ở Việt Nam | C29: TS.Mai Thị Thanh Xuân ThS.Ngô Đăng Thành | D29: QLP | E29: 1 | F29: 530 | G29: 236 | H29: 13x19 | I29: 30000 | J29: Đảng | K29: 19/1/2007 | L29: Tiến bộ | M29: Ko có | N29: Ko có
A30: 29 | B30: Quy định về xử phạt vi phạm hành chính trong hoạt động văn hóa-thông tin và văn bản có liên quan | C30: QH | D30: QLP | E30: 1 | F30: 1000 | G30: 256 | H30: 14,5x20,5 | I30: 25000 | J30: Quốc tế | K30: 19/1/2007 | L30: XN In và Văn hóa phẩm Bến Thành | M30: Ko có | N30: Ko có
A31: 30 | B31: Luật hàng không dân dụng Việt Nam và công ước về việc thống nhất một số quy tắc liên quan tới vận chuyển hàng không quốc tế | C31: QH | D31: QLP | E31: 1 | F31: 1000 | G31: 140 | H31: 14,5x20,5 | I31: 15000 | J31: Quốc tế | K31: 19/1/2007 | L31: XN In và Văn hóa phẩm Bến Thành | M31: Ko có | N31: Ko có
A32: 31 | B32: Luật luật sư, luật trợ giúp pháp lý và các văn bản có liên quan | C32: QH | D32: QLP | E32: 1 | F32: 1000 | G32: 120 | H32: 14,5x20,5 | I32: 13000 | J32: Quốc tế | K32: 19/1/2007 | L32: XN In và Văn hóa phẩm Bến Thành | M32: Ko có | N32: Ko có
... A39: 38 | B39: Quy định mới về thương mại điện tử | C39: QH | D39: CQ | E39: 1 | F39: 600 | G39: 104 | H39: 13x19 | I39: 10000 | J39: Pháp luật | K39: 26/1/2007 | L39: CTQG | M39: Ko có | N39: Ko có
A40: 39 | B40: Luật kiểm toán nhà nước và văn bản hướng dẫn thi hành | C40: QH | D40: CQ | E40: TB | F40: 1000 | G40: 100 | H40: 13x19 | I40: 10000 | J40: Pháp luật | K40: 26/1/2007 | L40: CTQG | M40: Ko có | N40: Ko có
A41: 40 | B41: Trường Chinh- Một tư duy sáng tạo, một tài năng kiệt xuất | C41: GS.Trần Nhâm | D41: CQ | E41: 1 | F41: 1000 | G41: 812 | H41: 14,5x20,5 | I41: 73000 | J41: Lý luận | K41: 26/1/2007 | L41: CTQG | M41: Ko có | N41: Ko có
A42: 41 | B42: Mối quan hệ Đảng-Nhà nước-Dân trong cuộc sống | C42: Nguyễn Khánh | D42: CQ | E42: 1 | F42: 600 | G42: 388 | H42: 15,5x23,5 | I42: 50000 | J42: Kinh điển | K42: 26/1/2007 | L42: CTQG | M42: Ko có | N42: Ko có
A43: 42 | B43: Những nghiên cứu tâm lý học | C43: Đỗ Long | D43: CQ | E43: 1 | F43: 500 | G43: 476 | H43: 16x24 | I43: 55000 | J43: Giáo khoa | K43: 26/1/2007 | L43: Văn hóa phẩm | M43: Ko có | N43: Ko có
A44: 43 | B44: Đánh giá tiến trình APEC và tác động đối với Việt Nam | C44: TS.Hoàng Anh Tuấn | D44: LK 1phần | E44: 1 | F44: 700 | G44: 260 | H44: 14,5x20,5 | I44: 34000 | J44: Lý luận | K44: 26/1/2007 | L44: CTQG | M44: Ko có | N44: Ko có
A45: 44 | B45: Một số lời dạy và mẩu chuyện về tấm gương đạo đức của Chủ tịch Hồ Chí Minh | C45: Ban TT-VHTW | D45: LKTG | E45: 1 | F45: 5000 | G45: 232 | H45: 13x19 | I45: 10000 | J45: Giáo khoa | K45: 26/1/2007 | L45: CTQG | M45: Có | N45: Ko có | O45: file word
A46: 45 | B46: Đẩy mạnh học tập và làm theo tấm gương đạo đức Hồ Chí Minh | C46: Ban TT-VHTW | D46: LKTG | E46: 1 | F46: 10000 | G46: 112 | H46: 13x19 | I46: 5000 | J46: Giáo khoa | K46: 26/1/2007 | L46: CTQG | M46: Ko có | N46: Ko có
...

Sheet 2008
A1: TT | B1: Tên sách | C1: Tác giả | D1: Phương thức | E1: Lần xuất bản | F1: Số lượng in | G1: Trang | H1: Khổ | I1: Giá bìa | J1: Ban biên tập | K1: QĐXB | L1: Nơi in | M1: Ghi chú
A2: 1 | B2: Hỏi đáp nghiệp vụ công tác Đảng dành cho Bí thư chi bộ và cấp ưy viên cơ sở | C2: PGS, TS. Đào Duy Quát PGS, TS. Phạm Văn Ninh | D2: QLP | E2: 1 | F2: 2000 | G2: 304 | H2: 14,5x20,5 | I2: 38000 | J2: KT | K2: 39453 | L2: Cty Cổ phần in 15
A3: 2 | B3: Lịch sử cuộc vận động vì các quyền dân sinh, dân chủ ở Việt Nam ( 1936 - 1939 ) | C3: Phạm Hồng Tung | D3: LKMP | E3: 1 | F3: 450 | G3: 204 | H3: 14,5x20,5 | I3: 30000 | J3: Đg | K3: 39455 | L3: CTQG
A4: 3 | B4: Dân chủ trong nghiên cứu khoa học xã hội và nhân văn: Một số vấn đề lý luận và thực tiễn | C4: GS,TS.Hoàng Chí Bảo | D4: LKMP | E4: 1 | F4: 500 | G4: 380 | H4: 14,5x20,5 | I4: 45000 | J4: KĐLL | K4: 39455 | L4: CTQG
A5: 4 | B5: Giáo trình lịch sử tỉnh Lào Cai | C5: Hội đồng Biên soạn tỉnh | D5: LKTG | E5: 1 | F5: 550 | G5: 200 | H5: 13x19 | I5: 52000 | J5: TTNCKHXB | K5: 39455 | L5: CTQG
A6: 5 | B6: Giáo trình địa lý tỉnh Lào Cai | C6: Hội đồng Biên soạn tỉnh | D6: LKTG | E6: 1 | F6: 550 | G6: 172 | H6: 13x19 | I6: 48000 | J6: QT | K6: 39455 | L6: CTQG
A7: 6 | B7: Phát triển kinh tế và bảo vệ chủ quyền biển, đảo Việt Nam | C7: Ban TGTW | D7: LKTG | E7: 1 | F7: 6000 | G7: 232 | H7: 14,5x20,5 | I7: Không giá | J7: GK | K7: 39455 | L7: Tiến Bộ
A8: 7 | B8: Những vấn đề lý luận và thực tiễn mới đặt ra trong tình hình hiện nay - Tập 1 | C8: HĐLLTW | D8: LKTG | E8: 1 | F8: 4500 | G8: 608 | H8: 14,5x20,5 | I8: 33500 | J8: QT | K8: 39455 | L8: CT In Công đoàn VN
A9: 8 | B9: Lịch sử Hội đồng nhân dân tỉnh Hà Tây ( 1946 - 2008 ) | C9: Thường trực HĐND Hà Tây | D9: LKTG | E9: 1 | F9: 1500 | G9: 606 | H9: 14,5x20,5 | I9: Không giá | J9: Văn phòng | K9: 39455 | L9: Công ty CP In Thái Nguyên
A10: 9 | B10: Luật khiếu nại tố cáo năm 1998; sửa đổi, bổ sung năm 2004, 2005 và các văn bản hướng dẫn thi hành | C10: QH | D10: TPH | E10: 1 | F10: 1370 | G10: 252 | H10: 13x19 | I10: 24500 | J10: PL | K10: 39455 | L10: CTQG
A11: 10 | B11: Tư tưởng Hồ Chí Minh về giáo dục thanh niên | C11: TS.Đoàn Nam Đàn | D11: TPH | E11: 1 | F11: 500 | G11: 252 | H11: 13x19 | I11: 25000 | J11: Đg | K11: 39455 | L11: CTQG
A12: 11 | B12: Vai trò của pháp luật trong đời sống xã hội | C12: TS.Nguyễn Minh Đoan | D12: TPH | E12: 1 | F12: 1040 | G12: 296 | H12: 13x19 | I12: 29500 | J12: PL | K12: 39455 | L12: CTQG
A13: 12 | B13: Quy định về chứng minh nhân dân và hộ chiếu | C13: QH | D13: TPH | E13: TB | F13: 1000 | G13: 136 | H13: 13x19 | I13: 15000 | J13: PL | K13: 39455 | L13: CTQG
A14: 13 | B14: Pháp lệnh thực hiện dân chủ ở xã, phường, thị trấn năm 2007 và văn bản hướng dẫn thi hành | C14: QH | D14: TPH | E14: 1 | F14: 2150 | G14: 64 | H14: 13x19 | I14: 8000 | J14: PL | K14: 39455 | L14: CTQG
A15: 14 | B15: Điều lệ Đảng Cộng sản Việt Nam | C15: ĐCSVN | D15: TPH | E15: TB | F15: 10000 | G15: 44 | H15: 12x20 | I15: 4500 | J15: Đg | K15: 39455 | L15: CTQG
A16: 15 | B16: Lược khảo về kinh nghiệm phát hiện, đào tạo và sử dụng nhân tài trong lịch sử Việt Nam | C16: Phạm Hồng Tung | D16: TPH | E16: 1 | F16: 500 | G16: 192 | H16: 14,5x20,5 | I16: 23000 | J16: Đg | K16: 39455 | L16: CTQG
A17: 16 | B17: Bóc lột - Cách nhìn và ứng xử | C17: Viện KHXHNV Quân sự | D17: TPH | E17: 1 | F17: 758 | G17: 268 | H17: 14,5x20,5 | I17: 33000 | J17: KT | K17: 39455 | L17: CTQG
A18: 17 | B18: Triết học giáo dục hiện đại | C18: Lương Vị Hùng Khổng Khang Hoa | D18: TPH | E18: 1 | F18: 473 | G18: 564 | H18: 14,5x20,5 | I18: 63000 | J18: KĐLL | K18: 39455 | L18: CTQG
A19: 18 | B19: Các văn bản pháp luật về chế độ, chính sách đối với cán bộ, công chức lực lượng vũ trang | C19: QH | D19: TPH | E19: 1 | F19: 600 | G19: 616 | H19: 14,5x20,5 | I19: 75000 | J19: PL | K19: 39455 | L19: CTQG
A20: 19 | B20: Công nghệ tiên tiến và công nghệ cao về tiến trình công nghiệp hoá hiện đại hoá ở Việt Nam | C20: TSKH Phan Xuân Dũng | D20: LKMP | E20: 1 | F20: 610 | G20: 272 | H20: 16x24 | I20: 83000 | J20: KT | K20: 39456 | L20: Nhà in Sự Thật
A21: 20 | B21: Tôn Trung Sơn cách mạng Tân Hợi và quan hệ Việt Nam - Trung Quốc | C21: Viện khoa học xã hội Việt Nam - Viện nghiên cứu Trung Quốc | D21: LKMP | E21: 1 | F21: 730 | G21: 176 | H21: 14,5x20,5 | I21: 25000 | J21: KĐLL | K21: 39456 | L21: Nhà in Sự Thật
A22: 21 | B22: Lịch sử công tác kiểm tra của Đảng bộ tỉnh Thái Bình (1930- 2008) | C22: Uỷ ban kiểm tra tỉnh uỷ Thái Bình | D22: LKTG | E22: 1 | F22: 830 | G22: 204 | H22: 14,5x20,5 | I22: 0 | J22: GK | K22: 39456 | L22: Công ty In Tiến Bộ
A23: 22 | B23: Lịch sử Tư tưởng Chính trị - xã hội Việt Nam. Từ Bắc thuộc đến thời Lý - Trần | C23: Lê Văn Quán | D23: TPH | E23: 1 | F23: 500 | G23: 324 | H23: 13x19 | I23: 34000 | J23: KĐLL | K23: 39456 | L23: Nhà in Sự Thật
A24: 23 | B24: Bộ luật tố tụng dân sự năm 2004 và Văn bản HDTH ( Tái bản có bổ sung ) | C24: QH | D24: TPH | E24: TB | F24: 680 | G24: 408 | H24: 19x27 | I24: 96000 | J24: PL | K24: 39456 | L24: Nhà in Sự Thật
A25: 24 | B25: Lịch sử phong trào nông dân và Hội nông dân tỉnh Sơn La (1940-2005) | C25: Ban chấp hành hội nông dân tỉnh Sơn La | D25: QLP | E25: 1 | F25: 1000 | G25: 380 | H25: 14,5x20,5 | I25: 0 | J25: VKHTK | K25: 39457 | L25: CTy in Cầu Giấy
A26: 25 | B26: Văn bản pháp luật về quản lý sản xuất, kinh doanh thuốc lá | C26: QH | D26: TPH | E26: 1 | F26: 180 | G26: 160 | H26: 13x19 | I26: 19000 | J26: PL | K26: 11/1/08 | L26: CTQG
A27: 26 | B27: Địa chí Hải Dương (CDROM ) | C27: Tỉnh uỷ HĐND- UBND tỉnh Hải Dương | D27: LKTG | E27: 1 | F27: 2130 | J27: KT | K27: 39459 | L27: Cty CP Đức Việt | M27: Quý IV 2008
A28: 27 | B28: Bàn về một số vấn đề ở nông thôn nước ta hiện nay | C28: GS, Hồ Văn Thông | D28: TPH | E28: 1 | F28: 410 | G28: 144 | H28: 14,5x20,5 | I28: 22000 | J28: QT | K28: 39459 | L28: Nhà in Sự Thật
A29: 28 | B29: Luật chất lượng sản phẩm, hàng hoá | C29: QH | D29: LKMP | E29: 1 | F29: 5000 | G29: 80 | H29: 13x19 | I29: 10000 | J29: PL | K29: 18/1/2008 | L29: CTQG
A30: 29 | B30: Luật phòng, chống bệnh truyền nhiễm | C30: QH | D30: LKMP | E30: 1 | F30: 4350 | G30: 56 | H30: 13x19 | I30: 8000 | J30: PL | K30: 18/1/2008 | L30: CTQG
A31: 30 | B31: Luật đặc xá | C31: QH | D31: LKMP | E31: 1 | F31: 4450 | G31: 32 | H31: 13x19 | I31: 6000 | J31: PL | K31: 18/1/2008 | L31: CTQG
A32: 31 | B32: Luật thuế thu nhập cá nhân | C32: QH | D32: LKMP | E32: 1 | F32: 6600 | G32: 36 | H32: 13x19 | I32: 6000 | J32: PL | K32: 18/1/2008 | L32: CTQG
A33: 32 | B33: Dạy và học môn tư tưởng Hồ Chí Minh theo phương pháp tích cực | C33: Nguyễn Đăng Quang | D33: LKTG | E33: TB | F33: 1540 | G33: 292 | H33: 14,5x20,5 | I33: 33000 | J33: GK | K33: 18/1/2008 | L33: CTQG
A34: 33 | B34: Nâng cao năng lực cạnh tranh của các doanh nghiệp Việt Nam trong xu thế hội nhập kinh tế quốc tế hiện nay | C34: TS.Nguyễn Hữu Thắng | D34: TPH | E34: 1 | F34: 700 | G34: 240 | H34: 14,5x20,5 | I34: 30000 | J34: GK | K34: 39465 | L34: CTQG
A35: 34 | B35: Văn bản hướng dẫn thi hành luật thống kê | C35: QH | D35: TPH | E35: 1 | F35: 410 | G35: 224 | H35: 13x19 | I35: 23000 | J35: PL | K35: 18/1/2008 | L35: CTQG
A36: 35 | B36: Tập bài giảng lịch sử nhà nước và pháp luật thế giới | C36: Ths. Nguyễn Minh Tuấn | D36: TPH | E36: 1 | F36: 670 | G36: 346 | H36: 14,5x20,5 | I36: 39000 | J36: PL | K36: 18/1/2008 | L36: CTQG
A37: 36 | B37: Tư duy kinh tế Hồ Chí Minh | C37: Cao Ngọc Thắng | D37: LKMP | E37: 1 | F37: 600 | G37: 264 | H37: 13x19 | I37: 27000 | J37: KĐLL | K37: 24/1/2008 | L37: CTQG
A38: 37 | B38: Nguyễn Đức Cảnh - Người con của giai cấp công nhân Việt Nam | C38: PGS,TS. Đức Vượng | D38: LKMP | E38: 1 | F38: 500 | G38: 172 | H38: 14,5x20,5 | I38: 22000 | J38: KĐLL | K38: 24/1/2008 | L38: CTQG
A39: 38 | B39: Giáo trình triết học Mác - Lênin Tập 1 - Chủ nghĩa duy vật biện chứng | C39: Học viện CT-HCQG Hồ Chí Minh | D39: QLP | E39: TB | F39: 540 | G39: 388 | H39: 14,5x20,5 | I39: 48000 | J39: KĐLL | K39: 24/1/2008 | L39: Công ty in Trung Sơn
A40: 39 | B40: Giáo trình triết học Mác - Lênin Tập 2 - Chủ nghĩa duy vật lịch sử | C40: Học viện CT-HCQG Hồ Chí Minh | D40: QLP | E40: TB | F40: 540 | G40: 404 | H40: 14,5x20,5 | I40: 50000 | J40: KĐLL | K40: 24/1/2008 | L40: Công ty in Trung Sơn
...

Sheet 2009
A1: NHÀ XUẤT BẢN CHÍNH TRỊ QUỐC GIA | E1: SÁCH XUẤT BẢN NĂM 2009
A2: VỤ KẾ HOẠCH THƯ KÝ BIÊN TẬP
A4: TT | B4: Tên sách | C4: Tác giả | D4: Phương thức | E4: Lần xuất bản | F4: Số lượng in | G4: Trang | H4: Khổ | I4: Giá bìa | J4: Ban biên tập | K4: QĐXB | L4: Nơi in | M4: Ghi chú
A5: 1 | B5: Trợ giúp pháp lý ở Việt Nam | C5: Tạ Thị Minh Lý | D5: LKTG | E5: 1 | F5: 10040 | G5: 136 | H5: 14,5x20,5 | I5: 0 | J5: PL | K5: 1/2009 | L5: Cty in Tiến Bộ
A6: 2 | B6: Hỏi - đáp về bảo hiểm thất nghiệp | C6: Lê Thanh | D6: TPH | E6: 1 | F6: 880 | G6: 144 | H6: 13x19 | I6: 18000 | J6: PL | K6: 39817 | L6: Nhà in Sự Thật
A7: 3 | B7: Con người chính trị Việt Nam truyền thống và hiện đại (Sách chuyên khảo) | C7: GS, TS. Nguyễn Văn Huyên | D7: TPH | E7: 1 | F7: 600 | G7: 368 | H7: 14,5x20,5 | I7: 48000 | J7: Đg | K7: 39820 | L7: Nhà in Sự Thật
A8: 4 | B8: Hồ Chí Minh với việc chữa bệnh làm mất dân chủ | C8: TS. Võ Văn Lộc Đại học Sài Gòn | D8: QLP | E8: 1 | F8: 1000 | G8: 278 | H8: 14,5x20,5 | I8: 55000 | J8: TPHCM | K8: 39823 | L8: Cty in Trần Phú 71-75 Hai Bà Trưng TPHCM | M8: Đã tính ĐM 2008
A9: 5 | B9: Công tác bảo vệ bí mật của Đảng, nhà nước ở các ban, cơ quan Đảng trực thuộc Trung ương. (Lưu hành nội bộ tại các ban, cơ quan Đảng, ban cán sự Đảng, Đảng đoàn và Đảng trực thuộc Trung ương (Mật ) | C9: Phan Văn Thọ | D9: TPH | E9: 1 | F9: 2000 | G9: 268 | H9: 14,5x20,5 | I9: 0 | J9: TTNCKH | K9: 13/01/2009 | L9: Nhà in Sự Thật
A10: 6 | B10: Phát huy những giá trị lịch sử, chính trị pháp lý của hiến pháp 1946 trong sự nghiệp đổi mới hiện nay (Sách tham khảo) | C10: Văn phòng Quốc hội CILRES TTTT - TViện và NCKH | D10: QLP | E10: 1 | F10: 1200 | G10: 316 | H10: 14,5x20,5 | I10: 0 | J10: QT | K10: 16/1/2009 | L10: CTy in và Xuất bản bao bì Hà Nội
A11: 7 | B11: Văn bản pháp luật về xử phạt hành chính trong lĩnh vưc du lịch khí tượng- thuỷ văn, rừng, giống cây, trồng và một số lĩnh vực khác | C11: QH | D11: TPH | E11: 1 | F11: 850 | G11: 436 | H11: 14,5x20,5 | I11: 57000 | J11: PL | K11: 16/01/2009 | L11: Nhà in Sự Thật
A12: 8 | B12: Chế định chứng cứ trong luật tố tụng hình sự Việt Nam Sách chuyên khảo (Tái bản có bổ sung) | C12: TS. Trần Quang Tiệp | D12: TPH | E12: TB | F12: 1000 | G12: 232 | H12: 13x19 | I12: 26000 | J12: PL | K12: 16/01/2009 | L12: Nhà in Sự Thật | M12: Đã tiính ĐM 2008
A13: 9 | B13: Tư tưởng ngoại giao Hồ Chí Minh | C13: Nguyễn Duy Niên | D13: TPH | E13: TB | F13: 500 | G13: 352 | H13: 14,5x20,5 | I13: 39000 | J13: QT | K13: 19/01/2009 | L13: Nhà in Hà Nội Cty sách Hà Nội
A14: 10 | B14: Hồ Chí Minh đỉnh cao truyền thống nhân trí dũng Việt Nam | C14: Nguyễn Khắc Nho | D14: TPH | E14: TB | F14: 500 | G14: 268 | H14: 13x20,50 | I14: 26000 | J14: QT | K14: 19/1/2009 | L14: Nhà In Sự Thật
A15: 11 | B15: Quy định mới về quản lý, cung cấp, sử dụng dịch vụ INTERNET, thông tin điện tử trên INTERNET. | C15: QH | D15: TPH | E15: 1 | F15: 550 | G15: 268 | H15: 13x19 | I15: 30000 | J15: PL | K15: 21/01/2009 | L15: Nhà in Sự Thật
A16: 12 | B16: Nhà nước trong hệ thống chính trị ở Việt Nam hiện nay | C16: PGS, TS. Lê Minh Quân | D16: TPH | E16: 1 | F16: 530 | G16: 168 | H16: 13x19 | I16: 20000 | J16: Đg | K16: 21/01/2009 | L16: Nhà in Sự Thật | M16: Đã tính ĐM 2008
A17: 13 | B17: Lịch sử phong trào công nhân lao động và hoạt động công đoàn tỉnh Trà Vinh (1929-2005) | C17: Liên đoàn lao động tỉnh Trà Vinh | D17: LKTG | E17: 1 | F17: 1200 | G17: 258 | H17: 14,5x20,5 | I17: 0 | J17: TPHCM | K17: 02/2009 | L17: Cty CP Văn hoá Tổng hợp Hưng Phú TPHCM
A18: 14 | B18: Giáo trình đường lối cách mạng của Đảng Cộng sản Việt Nam (Dành cho sinh viện đại học, cao đẳng khối không chuyên ngành Mác- Lênin, tư tưởng Hồ Chí Minh) | C18: Bộ Giáo dục và đào tạo | D18: QLP | E18: TB | F18: 8000 | G18: 264 | H18: 14,5x20,5 | I18: 18500 | J18: GK | K18: 02/2009 | L18: CTy CP in Nghệ An | M18: Sách in nối nộp LC
A19: 15 | B19: Giáo trình Tư tưởng Hồ Chí Minh (Dành cho sinh viên đại học, cao đẳng khối không chuyên ngành Mác- Lênin, tư tưởng Hồ Chí Minh) | C19: Bộ Giáo dục và đào tạo | D19: QLP | E19: TB | F19: 8000 | G19: 292 | H19: 14,5x20,5 | I19: 20500 | J19: GK | K19: 02/2009 | L19: CTy CP in Nghệ An | M19: Sách in nối nộp LC
A20: 16 | B20: Giáo trình những nguyên lý cơ bản của chủ nghiã Mác - Lênin (Dành cho sinh viên đại học, cao đẳng khối không chuyên ngành Mác - Lênin, tư tưởng Hồ Chí Minh) | C20: Bộ Giáo dục và đào tạo | D20: QLP | E20: TB | F20: 8000 | G20: 492 | H20: 14,5x20,5 | I20: 32500 | J20: GK | K20: 02/2009 | L20: Xí nghiệp in Tổng cục Công nghiệp Quốc phòng | M20: Sách in nối nộp LC
A21: 17 | B21: Giáo trình Tư tưởng Hồ Chí Minh (Dành cho sinh viên đại học, cao đẳng khối không chuyên ngành Mác- Lênin, tư tưởng Hồ Chí Minh) | C21: Bộ Giáo dục và đào tạo | D21: QLP | E21: 1 | F21: 20000 | G21: 292 | H21: 14,5x20,5 | I21: 20500 | J21: GK | K21: 02/2009 | L21: XN in ACS Việt Nam Dương Kinh Hải Phòng
A22: 18 | B22: Văn kiện Hội nghị lần thứ chín ban chấp hành Trung ương khoá X (Lưu hành nội bộ) | C22: Đảng Cộng sản Việt Nam | D22: TWĐH | E22: 1 | F22: 30040 | G22: 312 | H22: 13x19 | I22: 0 | J22: Đg | K22: 2/2009 | L22: Nhà in Sự Thật
A23: 19 | B23: 101 câu hỏi và trả lời về công tác tổ chức, kiểm tra của Đảng | C23: Hà Văn Thuật | D23: TPH | E23: 1 | F23: 1000 | G23: 332 | H23: 12x20,5 | I23: 44000 | J23: Đg | K23: 39847 | L23: Nhà in Sự Thật
A24: 20 | B24: Luật quản lý thuế năm 2006 và văn bản hướng dẫn thi hành | C24: QH | D24: TPH | E24: 1 | F24: 650 | G24: 784 | H24: 15x22 | I24: 114000 | J24: PL | K24: 39847 | L24: Nhà in Sự Thật
A25: 21 | B25: Địa chí Thái Nguyên | C25: Tỉnh uỷ - HĐND- UBND tỉnh Thái Nguyên | D25: LKTG | E25: 1 | F25: 2050 | G25: 1154 | H25: 21x29 | I25: 0 | J25: Đg | K25: 39848 | L25: Cty in và Văn hoá phẩm
A26: 22 | B26: Kỷ yếu hội nghị sơ kết 2 năm thực hiện cuộc vận động học tập và làm theo tấm gương đạo đức Hồ Chí Minh | C26: Ban chỉ đạo Trung ương cuộc vận động học tập và làm theo tấm gương đạo đức Hồ Chí Minh | D26: LKTG | E26: 1 | F26: 3030 | G26: 264 | H26: 13x19 | I26: 0 | J26: GK | K26: 39848 | L26: Cty in Thương mại Thông tấn xã Việt Nam
A27: 23 | B27: Luật phòng, chống ma tuý năm 2000 (Sửa đổi, bổ sung năm 2008) | C27: QH | D27: TPH | E27: 1 | F27: 1450 | G27: 92 | H27: 13x19 | I27: 12000 | J27: PL | K27: 39848 | L27: Nhà In Sự Thật
A28: 24 | B28: Sơn Tây - Thuận Hoá và anh hùng dân tộc Nguyễn Huệ Quang Trung | C28: Hội Khoa học lịch sử thừa thiên huế | D28: TPH | E28: 1 | F28: 780 | G28: 484 | H28: 14,5x20,5 | I28: 63000 | J28: Đg | K28: 39851 | L28: Nhà in Sự Thật
A29: 25 | B29: Một số vấn đề về quản lý Nhà Nước trong nền kinh tế thị trường định hướng xã hội chủ nghĩa ở Việt Nam (Sách tham khảo) | C29: GS, TS. Từ Điển | D29: TPH | E29: 1 | F29: 500 | G29: 340 | H29: 14,5x20,5 | I29: 45000 | J29: GK | K29: 39851 | L29: Nhà in Sự Thật
A30: 26 | B30: Hỏi - Đáp về luật phòng, chống bạo lực gia đình | C30: Lan Anh | D30: TPH | E30: 1 | F30: 1150 | G30: 116 | H30: 13x19 | I30: 15000 | J30: PL | K30: 39851 | L30: Nhà in Sự Thật
A31: 27 | B31: Nhà nước cách mạng Việt Nam những năm 1945 - 1946 những sách tạo của Hồ Chí Minh | C31: TS. Lê Phương Thảo | D31: QLP | E31: 1 | F31: 300 | G31: 204 | H31: 14,5x20,5 | I31: 45000 | J31: GK | K31: 39855 | L31: Công ty in Giao thông | M31: Báo cáo QIV
A32: 28 | B32: Hồ Chí Minh trong ký ức bạn bè Quốc Tế | C32: Đỗ Hoàng Linh Phạm Hoàng Hiệp (Biên soạn) | D32: TPH | E32: 1 | F32: 700 | G32: 204 | H32: 14,5x20,5 | I32: 29000 | J32: QT | K32: 39855 | L32: Nhà in Sự Thật
A33: 29 | B33: Hồ Chí Minh từ Pác Bó đến Ba Đình | C33: Đỗ Hoàng Ninh (Biên soạn) | D33: TPH | E33: 1 | F33: 500 | G33: 296 | H33: 14,5x20,5 | I33: 40000 | J33: QT | K33: 13/02/2009 | L33: Nhà In Sự Thật
A34: 30 | B34: Tài liệu Học tập Chính trị dành cho học viên lớp bồi dưỡng kết nạp Đảng (Tái bản có sửa chữa bổ sung) | C34: Ban tuyên giáo Trung ương | D34: TPH | E34: TB | F34: 8000 | G34: 192 | H34: 13x19 | I34: 15500 | J34: GK | K34: 17/02/2009 | L34: Nhà in Sự Thật
A35: 31 | B35: Học thuyết phạm trù trong triết học Mác- Lênin | C35: Lê Công Sự , Hoàng Thị Hạnh | D35: TPH | E35: 1 | F35: 820 | G35: 284 | H35: 15x22 | I35: 44000 | J35: GK | K35: 17/02/2009 | L35: Nhà in Sự thật
A36: 32 | B36: Phong trào công nhân quốc tế - Những vấn đề lịch sử và lý luận. Tập III | C36: Hội đồng xuất bản | D36: TWĐH | E36: 1 | F36: 1000 | G36: 1180 | H36: 15x22 | I36: 167000 | J36: KĐLL | K36: 17/02/2009 | L36: Cty in Tiến Bộ
A37: 33 | B37: Phong trào công nhân quốc tế - Những vấn đề lịch sử và lý luận. Tập IV | C37: Hội đồng xuất bản | D37: TWĐH | E37: 1 | F37: 1000 | G37: 1344 | H37: 15x22 | I37: 174000 | J37: KĐLL | K37: 17/02/2009 | L37: Cty in Tiến Bộ
A38: 34 | B38: Xử lý văn bản quản lý hành chính nhà nước khiếm khuyết (Sách chuyên khảo) | C38: TS. Nguyễn Thế Quyền | D38: QLP | E38: 1 | F38: 2000 | G38: 412 | H38: 14,5x20,5 | I38: 60000 | J38: PL | K38: 18/02/2009 | L38: CTy in Tổng hợp Cầu Giấy
A39: 35 | B39: Các vùng, tỉnh , thành phố trực thuộc Trung ương: Tiềm năng và triển vọng đến năm 2020 | C39: Bộ kế hoạch và đầu tư viện chiến lược phát triển | D39: QLP | E39: 1 | F39: 500 | G39: 690 | H39: 20,5x26,5 | I39: 45000 | J39: KT | K39: 18/02/2009 | L39: Nhà in Sự Thật
A40: 36 | B40: Vấn đề nông nghiệp, nông dân, nông thôn - kinh nghiệm của Việt Nam, kinh nghiệm của Trung Quốc (Sách tham khảo) | C40: GS. TS Phùng Hữu Phú TS. Nguyễn Viết Thông TS. Bùi Văn Thông | D40: LKTG | E40: 1 | F40: 5000 | G40: 500 | H40: 15x22 | I40: 32000 | J40: QT | K40: 19/02/2009 | L40: Cty in Tiến Bộ
A41: 37 | B41: Lịch sử bộ đội biên phòng tỉnh Bình Phước (1975-2005) | C41: Bộ Tư lệnh bộ đội biên phòng Bộ chỉ huy bộ đội biên phòng tỉnh Bình Phước | D41: LKTG | E41: 1 | F41: 800 | G41: 418 | H41: 14,5x20,5 | I41: 0 | J41: TPHCM | K41: 20/02/2009 | L41: Cty CP Hưng Phú TP- HCM
...

Sheet 2010
A1: SÁCH XUẤT BẢN NĂM 2010
A3: TT | B3: Tên sách | C3: Tác giả | D3: Phương thức | E3: Lần XB | F3: Số lượng in | G3: Số trang | H3: Khổ sách | I3: Giá bìa | J3: Ban biên tập | K3: QĐXB
A5: 1 | B5: Văn kiện đại hội đại biểu toàn quốc lần thứ VII | C5: Mặt trận tổ quốc Việt Nam | D5: LKTG | E5: 1 | F5: 2500 | G5: 160 | H5: 14,5x20,5 | J5: KĐLL | K5: 1/2010
A6: 2 | B6: Luật ban hành văn bản quy phạm pháp luật năm 2008 và nghị định hướng dẫn thi hành * Luật ban hành văn bản quy phạm pháp luật năm 2008 * Ng | C6: QH, CP | D6: TPH | E6: 1 | F6: 500 | G6: 168 | H6: 13x19 | J6: PL | K6: 1/2010
A7: 3 | B7: Đảng Cộng sản Việt Nam 80 năm xây dựng và phát triển | C7: Hội đồng xuất bản | D7: TWDH | E7: 1 | F7: 1500 | G7: 1228 | H7: 16x24 | J7: Đảng | K7: 40179
A8: 4 | B8: Phong trào đồng khởi 50 năm nhìn lại | C8: Tập thể tác giả | D8: TWDH | E8: 1 | F8: 1000 | G8: 616 | H8: 16x24 | J8: Đảng | K8: 1/2010
A9: 5 | B9: Tư tưởng, tấm gương đạo đức Hồ Chí Minh về xây dựng đảng ta thật sự trong sạch, vững mạnh " Là đạo đức, là văn minh" (Tài liệu tham khảo phục vụ nghiên cứu, học tập chủ đề năm 2010 Cuộc vận động " Học tập và làm theo tấm gương đạo đức Hồ Chí Minh" ) | C9: Ban Tuyên giáo Trung ương | D9: LKTG | E9: 1 | F9: 10030 | G9: 248 | H9: 13x19 | J9: GK | K9: 1/2010
A10: 6 | B10: Đề cương học tập chủ đề Tư tưởng, tấm gương đạo đức Hồ Chí Minh về xây dựng đảng ta thật sự trong sạch, vững mạnh " Là đạo đức, là văn minh" (Tài liệu học tập chủ đề năm 2010 Cuộc vận động " Học tập và làm theo tấm gương đạo đức Hồ Chí Minh" dành cho cán | C10: Ban Tuyên giáo Trung ương | D10: LKTG | E10: 1 | F10: 100000 | G10: 30 | H10: 13x19 | J10: GK | K10: 1/2010
A11: 7 | B11: Luật di sản văn hóa năm 2001 được sửa đổi, bổ sung năm 2009 | C11: QH,CP | D11: TPH | E11: 1 | F11: 2000 | G11: 80 | H11: 13x19 | J11: PL | K11: 1/2010
A12: 8 | B12: Phong cách làm việc của người bí thư huyện uỷ hiện nay qua khảo sát vùng đồng bằng sông Hồng (Sách chuyên khảo) | C12: TS. Ngô Kim Ngân- TS. Lâm Quốc Tuấn (Đồng chủ biên) | D12: TPH | E12: 1 | F12: 700 | G12: 232 | H12: 14,5x20,5 | J12: Đảng | K12: 1/2010
A13: 9 | B13: Đại thắng mùa xuân 1975 Sự kiện - Hỏi và Đáp | C13: Hội đồng chỉ đạo xuất bản sách xã phường thị trấn | D13: TPH | E13: 1 | F13: 9000 | G13: 200 | H13: 12,5x20,5 | J13: QT | K13: 1/2010
A14: 10 | B14: Hỏi - Đáp về tiếp dân và giải quyết khiếu nại, tố cáo của chính quyền cấp xã | C14: Hội đồng chỉ đạo xuất bản sách xã phường thị trấn | D14: TPH | E14: 1 | F14: 9000 | G14: 68 | H14: 12,5x20,5 | J14: GK | K14: 1/2010
A15: 11 | B15: Hỏi - Đáp pháp luật về bồi thường thiệt hại, hỗ trợ tái định cư khi nhà nước thu hồi đất | C15: Hội đồng chỉ đạo xuất bản sách xã phường thị trấn | D15: TPH | E15: 1 | F15: 9000 | G15: 280 | H15: 12,5x20,5 | J15: PL | K15: 1/2010
A16: 12 | B16: Luật phòng cháy và chữa cháy và văn bản hướng dẫn thi hành (Tái bản có bổ sung) | C16: QH, CP | D16: TPH | E16: TB | F16: 600 | G16: 408 | H16: 14,5x20,5 | J16: PL | K16: 1/2010
A17: 13 | B17: Luật phòng, chống ma tuý năm 2000 được sửa đổi bổ sung năm 2008 và văn bản hướng dẫn thị hành | C17: QH, CP | D17: TPH | E17: 1 | F17: 1150 | G17: 204 | H17: 13x19 | J17: PL | K17: 1/2010
A18: 14 | B18: Cẩm nang về công tác bồi thường hỗ trợ tái định cư khi nhà nước thu hồi đất | C18: TS. Nguyễn Thị Phượng | D18: TPH | E18: 1 | F18: 620 | G18: 140 | H18: 13x19 | J18: PL | K18: 1/2010
A19: 15 | B19: Hỏi - Đáp về chứng minh nhân dân và hộ chiếu | C19: Hội đồng chỉ đạo xuất bản sách xã phường thị trấn | D19: TPH | E19: 1 | F19: 9000 | G19: 76 | H19: 12,5x20,5 | J19: PL | K19: 1/2010
A20: 16 | B20: Hỏi - Đáp về bảo vệ an ninh trật tự ở cơ sở | C20: Hội đồng chỉ đạo xuất bản sách xã phường thi trấn | D20: TPH | E20: 1 | F20: 9000 | G20: 84 | H20: 12,5x20,5 | J20: PL | K20: 1/2010
A21: 17 | B21: Uỷ ban Trung ương Mặt trận Tổ quốc Việt Nam khoá VII | C21: Mặt trận tổ quốc Việt Nam | D21: LKTG | E21: 1 | F21: 1000 | G21: 152 | H21: 19x25 | J21: KĐLL | K21: 01/2010
A22: 18 | B22: Nhà nước pháp quyền Xã hội chủ nghĩa Việt Nam của dân, do dân, vì dân.Lý luận và thực tiễn | C22: GS, VS. Nguyễn Duy Quý PGS, TS. Nguyễn Tất Viễn (Đồng chủ biên) | D22: TPH | E22: 1 | F22: 560 | G22: 376 | H22: 14,5x20,5 | J22: KĐLL | K22: 01/2010
A23: 19 | B23: Cẩm nang Công tác đảng | C23: Hội đồng chỉ đạo xuất bản sách xã phường, thị trấn | D23: TPH | E23: 1 | F23: 9000 | G23: 272 | H23: 12,5x20,5 | J23: KĐLL | K23: 01/2010
A24: 20 | B24: Luật hình sự Việt Nam Quyển 2 (Phần các tội phạm) | C24: TS. Phạm Văn Beo | D24: TPH | E24: 1 | F24: 2000 | G24: 660 | H24: 16x24 | J24: PL | K24: 1/2010
A25: 21 | B25: Bình luận luật sửa đổi bổ sung một số điều của bộ luật hình sự năm 1999 | C25: GS, TS. Nguyễn Ngọc Anh Ths. Đỗ Khắc Hưởng | D25: TPH | E25: 1 | F25: 1020 | G25: 112 | H25: 16x24 | J25: PL | K25: 01/2010
A26: 22 | B26: Hỏi - Đáp về dân chủ ở cơ sở | C26: Hội đồng chỉ đạo xuất bản sách xã, phường, thị trấn | D26: TPH | E26: 1 | F26: 9000 | G26: 132 | H26: 12,5x20,5 | J26: PL | K26: 1/2010
A27: 23 | B27: Hỏi - Đáp về cải cách thủ tục trong hoạt động thu, nộp thuế | C27: Hội đồng chỉ đạo xuất bản sách, xã phường, thị trấn | D27: TPH | E27: 1 | F27: 9000 | G27: 228 | H27: 12,5x20,5 | J27: PL | K27: 1/2010
A28: 24 | B28: Quản lý, chỉ đạo công tác tư pháp xã, phường, thị trấn | C28: Hội đồng chỉ đạo xuất bản sách xã phường, thị trấn | D28: TPH | E28: 1 | F28: 9000 | G28: 212 | H28: 12,5x20,5 | J28: PL | K28: 1/2010
... A36: 32 | B36: Cuộc tổng tiến công của quân giải phóng miền Nam Việt Nam năm 1968 (Qua tài liệu lưu trữ của chính quyền Sài Gòn) | C36: Trung tâm lưu trữ Quốc gia | D36: LKTG | E36: 1 | F36: 600 | G36: 400 | H36: 16x24 | J36: PL | K36: 1/2010
A37: 33 | B37: Giáo trình chủ nghĩa xã hội khoa học (Tái bản có sửa chữa bổ sung) | C37: Hội đồng chỉ đạo biên soạn | D37: TPH | E37: TB | F37: 500 | G37: 560 | H37: 14,5x20,5 | J37: GK | K37: 1/2010
A38: 34 | B38: Bình luận khoa học bộ luật dân sự năm 2005 (Tập III) Phần thứ tư: Thừa kế Phần thứ năm: Quy dịnh về chuyển quyền sử dụng đất Phần thứ sáu: Quyền sở hữu trí tuệ | C38: Bộ Tư pháp viện khoa học pháp lý GS, TS. Hoàng Thế Liên | D38: TPH | E38: 1 | F38: 2200 | G38: 612 | H38: 16x24 | J38: PL | K38: 1/2010
A39: 35 | B39: Tư tưởng Hồ Chí Minh về kinh tế | C39: HVBCTT TS. Ngô Văn Lương | D39: LKTG | E39: 1 | F39: 1030 | G39: 304 | H39: 13x19 | J39: KT | K39: 1/2010
A40: 36 | B40: Lịch sử Đảng bộ xã An Bình (1975 - 2005) | C40: Đảng bộ Huyện Dĩ An BCH Đảng bộ xã An Bình | D40: LKTG | E40: 1 | F40: 530 | G40: 216 | H40: 14,5x20,5 | J40: TPHCM | K40: 1/2010
A41: 37 | B41: Khu di tích lịch sử Tân Trào | C41: Ngô Quân Lập | D41: LKTG | E41: TB | F41: 2000 | G41: 192 | H41: 13x19 | J41: KĐLL | K41: 40184
A42: 38 | B42: Lịch sử truyền thống công an quận Hoàn Kiếm (1945 - 2010) | C42: Công an quận Hoàn Kiếm | D42: LKTG | E42: 1 | F42: 500 | G42: 276 | H42: 14,5x20,5 | J42: TTNCKH | K42: 40186
A43: 39 | B43: Quan hệ kinh tế giữa công nhân, nông dân và trí thức ở Việt Nam hiện nay | C43: Đặng Quang Định | D43: TPH | E43: 1 | F43: 640 | G43: 220 | H43: 13x19 | J43: KĐLL | K43: 40186
A44: 40 | B44: Tư tưởng Hồ Chí Minh về hợp tác xã những vấn đề lý luận và thực tiễn | C44: GS, TS. Lê Hữu Nghĩa | D44: TPH | E44: 1 | F44: 850 | G44: 492 | H44: 16x24 | J44: KT | K44: 40189
A45: 41 | B45: Một số giải pháp nhằm phát triển bền vững nông thôn vùng đồng bằng Bắc bộ trong quá trình xây dựng, phát triển các khu công nghiệp (Qua khảo sát các tỉnh Vĩnh Phúc, Hải Dương, Ninh Bình) | C45: TS Đỗ Đức Quân | D45: TPH | E45: 1 | F45: 500 | G45: 168 | H45: 14,5x20,5 | J45: KĐLL | K45: 40190
A46: 42 | B46: Lợi Nhuận (Sách tham khảo) | C46: TS. Trần Xuân Kiên | D46: TPH | E46: 1 | F46: 680 | G46: 216 | H46: 14,5x20,5 | J46: KĐLL | K46: 40190
A47: 43 | B47: Phát huy tính tích cực xã hội của đội ngũ cán bộ nước ta hiện nay (Tái bản có sửa chữa bổ sung) | C47: PGS, TS. Nguyễn Văn Tài | D47: TPH | E47: 1 | F47: 680 | G47: 248 | H47: 14,5x20,5 | J47: GK | K47: 13/01/2010
A48: 44 | B48: Tham luận tại đại hội đại biểu toàn quốc lần thứ VII | C48: Mặt trận tổ quốc Việt Nam | D48: LKTG | E48: 1 | F48: 1000 | G48: 656 | H48: 14,5x20,5 | J48: KĐLL | K48: 22/1/2010
A49: 45 | B49: Lịch sử Đảng bộ và nhân dân xã Thái Hà (1927 - 2005) | C49: Ban chấp hành đảng bộ xã Thái Hà | D49: LKTG | E49: 1 | F49: 350 | G49: 432 | H49: 14,5x20,5 | J49: KĐLL | K49: 25/01/2010
...

Sheet 2011
A1: SÁCH XUẤT BẢN NĂM 2011
A2: TT | B2: Tên sách | C2: Tác giả | D2: Phương thức | E2: Lần xuất bản | F2: SL in | G2: Trang | H2: Khổ | I2: Giá bìa | J2: BBT | K2: QĐXB | L2: Nơi in | M2: Ghi chú
A3: 1 | B3: Tuyên ngôn độc lập của Chủ tịch Hồ Chí Minh - Giá trị lý luận và ý nghĩa thời đại | C3: Bảo tàng Hồ Chí Minh | D3: TPH | E3: 1 | F3: 690 | G3: 408 | H3: 16x24 | I3: 79000 | J3: Đg | K3: 1/2011 | L3: Cty TNHH MTV in Văn Hoá phẩm
A4: 2 | B4: Phong trào công nhân quốc tế -những vấn đề lịch sử và lý luận, tập VII (Sách tham khảo) | C4: Hội đồng xuất bản | D4: TWĐH | E4: 1 | F4: 1000 | G4: 1092 | H4: 15x22 | I4: 155000 | J4: KĐLL | K4: 1/2011 | L4: Cty in Tiến Bộ Hà Nội | M4: 14/1/2011
A5: 3 | B5: Đổi mới công tác tư tưởng, lý luận phục vụ sự nghiệp xây dựng và bảo vệ Tổ quốc | C5: TS. Phạm Tất Thắng (Chủ biên) | D5: TPH | E5: 1 | F5: 7000 | G5: 364 | H5: 14.5x20.5 | I5: 48000 | J5: TTPH | K5: 1/1/2011 | L5: Cty Cp in Thái Nguyên | M5: Sách 2010 NLC 14/1/2011
A6: 4 | B6: 80 năm (1930-2010) Đảng Cộng sản Việt Nam - những chặng đường lịch sử vẻ vang | C6: PGS.TS. Vũ Như Khôi | D6: TPH | E6: 1 | F6: 830 | G6: 700 | H6: 16x24 | I6: 0 | J6: QT | K6: 1/2011 | L6: Cty CP in Thiên Kim | M6: Sách 2010 NLC 14/1/2011
A7: 5 | B7: Hồ Chí Minh toàn tập (Xuất bản lần thứ ba), tập 1 1912 - 1924 | C7: Hội đồng xuất bản | D7: TWĐH | E7: TB | F7: 1500 | G7: 576 | H7: 16x24 | I7: 0 | J7: Đg | K7: 1/2011 | L7: Cty in Tiến Bộ
A8: 6 | B8: Hồ Chí Minh toàn tập (Xuất bản lần thứ ba), tập 2 1924 - 1929 | C8: Hội đồng xuất bản | D8: TWĐH | E8: TB | F8: 1500 | G8: 650 | H8: 16x24 | I8: 0 | J8: Đg | K8: 1/2011 | L8: Cty in Tiến Bộ
A9: 7 | B9: Hồ Chí Minh toàn tập (Xuất bản lần thứ ba), tập 3 1930 - 1945 | C9: Hội đồng xuất bản | D9: TWĐH | E9: TB | F9: 1500 | G9: 700 | H9: 16x24 | I9: 0 | J9: Đg | K9: 1/2011 | L9: Cty in Tiến Bộ
A10: 8 | B10: Giáo trình Tư tưởng Hồ Chí Minh (Tái bản có sửa chữa, bổ sung) | C10: Hội đồng Trung ương chỉ đạo biên soạn giáo trình quốc gia các bộ môn khoa học Mác- Lênin, tư tưởng Hồ Chí Minh | D10: TPH | E10: TB | F10: 1000 | G10: 492 | H10: 14,5x20,5 | I10: 66000 | J10: GK | K10: 1/2011 | L10: Nhà in Sự Thật
A11: 9 | B11: Vai trò của các tổ chức xã hội đối với phát triển và quản lý xã hội | C11: TS. Thang Văn Phúc, PGS, TS. Nguyễn Minh Phương (Đồng Chủ biên) | D11: TPH | E11: 1 | F11: 800 | G11: 592 | H11: 14,5x20,5 | I11: 83000 | J11: GK | K11: 1/2011 | L11: Nhà in Sự Thật
A12: 10 | B12: Recognizing and reducing corruption risks in land management in Vietnam (Reference book) | C12: The world bank in Vietnam, Embassy of Denmark, Embassy of Sweden | D12: LKTG | E12: 1 | F12: 300 | G12: 76 | H12: 19x24 | I12: 0 | J12: PL | K12: 1/2011 | L12: Cty in Tạp chí cộng sản
A13: 11 | B13: Luật thuế tài nguyên | C13: QH, CP | D13: TPH | E13: TB | F13: 1500 | G13: 20 | H13: 13x19 | I13: 5000 | J13: PL | K13: 1/2011 | L13: Cty TNHH NTV in và Văn Hoá Phẩm | M13: Sách 31/12/2010 nộp LC 28/1/2011
A14: 12 | B14: Dân chủ nhân quyền - giá trị toàn cầu và đặc thù quốc gia (Lưu hành nội bộ) | C14: Hội đồng Lý luận Trung ương | D14: TWĐH | E14: 1 | F14: 1000 | G14: 472 | H14: 16x24 | I14: 0 | J14: KT | K14: 40544 | L14: CtyTNHH MTV in và Văn hoá phẩm
A15: 13 | B15: Thanh Hoá một thời để nhớ | C15: Hồ Mẫu Ngoạt | D15: LKTG | E15: 1 | F15: 300 | G15: 424 | H15: 14,5x20,5 | I15: 0 | J15: Đg | K15: 40544 | L15: Cty in Tiến Bộ
A16: 14 | B16: Xác định tiêu chuẩn và phương pháp đánh giá chính quyền xã trong sạch, vững mạnh | C16: TS. Nguyễn Hữu Đức, Ths. Phan Văn Hùng (Đồng chủ biên) | D16: TPH | E16: TB | F16: 534 | G16: 176 | H16: 13x19 | I16: 27000 | J16: Đg | K16: 1/2011 | L16: Nhà in Sự Thật
A17: 15 | B17: Luật quốc tịch Việt Nam năm 2008 và văn bản hướng dẫn thi hành (Tái bản có bổ sung) | C17: QH, CP | D17: TPH | E17: TB | F17: 1000 | G17: 192 | H17: 13x19 | I17: 27000 | J17: PL | K17: 1/2011 | L17: Nhà in Sự Thật
A18: 16 | B18: Hỏi - Đáp một số vấn đề về các tội xâm phạm trật tự quản lý hành chính trong Bộ luật hình sự hiện hành | C18: TS. Nguyễn Vũ Tiến, TS. Đỗ Đức Hồng Hà | D18: TPH | E18: 1 | F18: 950 | G18: 92 | H18: 13x19 | I18: 15000 | J18: PL | K18: 1/2011 | L18: Nhà in Sự Thật
A19: 17 | B19: Luật thi đua, khen thưởng năm 2003 (Sửa đổi, bổ sung năm 2005, 2009 và văn bản hướng dẫn thi hành) | C19: QH, CP | D19: TPH | E19: 1 | F19: 1000 | G19: 204 | H19: 13x19 | I19: 23000 | J19: PL | K19: 1/2011 | L19: Nhà in Sự Thật | Q19: 540
A20: 18 | B20: Chế định chứng cứ trong Luật tố tụng hình sự Việt Nam (sách chuyên khảo) | C20: TS. Trần Quang Tiệp | D20: TPH | E20: TB | F20: 485 | G20: 232 | H20: 13x19 | I20: 34000 | J20: PL | K20: 1/2011 | L20: Nhà in Sự Thật
A21: 19 | B21: Luật cán bộ, công chức năm 2008 và văn bản hướng dẫn thi hành | C21: QH, CP | D21: TPH | E21: TB | F21: 1250 | G21: 260 | H21: 13x19 | I21: 27000 | J21: PL | K21: 1/2011 | L21: Nhà in Sự Thật
A22: 20 | B22: Trào lưu xã hội dân chủ ở một số nước phương Tây hiện nay (sách tham khảo) | C22: Tống Đức Thảo, Bùi Việt Phương (Đồng chủ biên) | D22: TPH | E22: 1 | F22: 600 | G22: 244 | H22: 14,5x20,5 | I22: 40000 | J22: KĐLL | K22: 1/2011 | L22: Nhà in Sự Thật
A23: 21 | B23: Lịch sử Đảng bộ và nhân dân xã Vĩnh Thạch (1930-2009) | C23: Huyện ủy Vĩnh Linh | D23: LKTG | E23: 1 | F23: 250 | G23: 284 | H23: 14,5x20,5 | I23: 0 | J23: GK | K23: 1/2011 | L23: Cty in Thống kê và sản xuất bao bì Huế
A24: 22 | B24: Văn kiện Đảng về an sinh xã hội | C24: Hội đồng biên soạn | D24: TWĐH | E24: 1 | F24: 1000 | G24: 296 | H24: 16x24 | I24: 0 | J24: KT | K24: 1/2011 | L24: Cty TNHH MTV in và Văn hoá phẩm
A25: 23 | B25: Nhận diện và giảm thiểu các rủi ro dẫn đến tham nhũng trong quản lý đất đai ở Việt Nam (sách tham khảo) | C25: Ngân hàng thế giới tại Việt Nam, Đại sứ quán Đan Mạch | D25: LKTG | E25: 1 | F25: 2000 | G25: 72 | H25: 19x24 | I25: 0 | J25: PL | K25: 1/2011 | L25: Cty in Tạp chí cộng sản | M25: BCTTết (8-18/2/2011)
A26: 24 | B26: Quá trình đổi mới tư duy lý luận của Đảng từ năm 1986 đến nay | C26: HVCT - HCQG TP HCM, Tô Huy Rứa, Hoàng Chí Bảo, Trần Khắc Việt, Lê Ngọc Tòng (Đồng chủ biên) | D26: TPH | E26: TB | F26: 534 | G26: 524 | H26: 16x24 | I26: 105000 | J26: KĐLL | K26: 1/2011 | L26: Nhà in Sự Thật
A27: 25 | B27: Chủ nghĩa Mác - Lênin với vận mệnh và tương lai của chủ nghĩa xã hội hiện thực (Xuất bản lần thứ hai) | C27: GS, TS. Nguyễn Ngọc Long (Chủ biên) | D27: TPH | E27: TB | F27: 534 | G27: 532 | H27: 14,5x20,5 | I27: 80000 | J27: KĐLL | K27: 1/2011 | L27: Nhà in Sự Thật
A28: 26 | B28: Học thuyết bảo vệ Tổ quốc xã hội chủ nghĩa của V. I. Lênin - giá trị lịch sử và hiện thực | C28: Viện khoa học xã hội nhân văn quân sự | D28: TPH | E28: 1 | F28: 680 | G28: 396 | H28: 14,5x20,5 | I28: 59000 | J28: Đg | K28: 1/2011 | L28: Nhà in Sự Thật
A29: 27 | B29: Luật dân quân tự vệ | C29: QH, CP | D29: TPH | E29: 1 | F29: 2000 | G29: 60 | H29: 13x19 | I29: 10000 | J29: PL | K29: 1/2011 | L29: Nhà in Sự Thật | M29: BCT (21-26/2/2011)
A30: 28 | B30: Văn kiện Quốc hội Toàn tập, tập 7 (1987-1992) Quyển 1 (1987-1989) | C30: Quốc hội nước Cộng hoà xã hội chủ nghĩa Việt Nam | D30: LKTG | E30: 1 | F30: 1600 | G30: 1480 | H30: 16x24 | I30: 0 | J30: PL | K30: 40513 | L30: Cty in Tiến Bộ Hà Nội
A31: 29 | B31: Văn kiện Quốc hội Toàn tập, tập 7 (1987-1992) Quyển 2 (1989-1990) | C31: Quốc hội nước Cộng hoà xã hội chủ nghĩa Việt Nam | D31: LKTG | E31: 1 | F31: 1600 | G31: 1772 | H31: 16x24 | I31: 0 | J31: PL | K31: 12/2010 | L31: Cty in Tiến Bộ Hà Nội
A32: 30 | B32: Lịch sử Tây Nam Bộ kháng chiến, tập 1 (1945 - 1954) | C32: Hội đồng chỉ đạo biên soạn | D32: TWĐH | E32: 1 | F32: 1800 | G32: 956 | H32: 16x24 | I32: 0 | J32: GK | K32: 1/2011 | L32: Cty in Tiến Bộ Hà Nội
A33: 31 | B33: Chất lượng tăng trưởng kinh tế Đồng Nai (Sách tham khảo) | C33: Sở KH và CN Đồng Nai, PGS, TS. Ngô Quang Minh, TS. Nguyễn Trọng Toàn, TS. Phạm Văn Sáng, TS. Bùi Văn Huyền | D33: TPH | E33: 1 | F33: 570 | G33: 320 | H33: 14,5x20,5 | I33: 58000 | J33: QT | K33: 1/2011 | L33: Nhà in Sự Thật
A34: 32 | B34: Chính sách phát triển thị trường bất động sản ở Việt Nam | C34: TS. Đinh Văn Ân (Chủ biên) | D34: TPH | E34: 1 | F34: 930 | G34: 464 | H34: 14,5x20,5 | I34: 65000 | J34: KT | K34: 1/2011 | L34: Nhà in Sự Thật
A35: 33 | B35: Luật phòng cháy và chữa cháy và văn bản hướng dẫn thi hành (Tái bản có BS) | C35: QH, CP | D35: TPH | E35: TB | F35: 1034 | G35: 408 | H35: 14,5x20,5 | I35: 56000 | J35: PL | K35: 1/2011 | L35: Nhà in Sự Thật
A36: 34 | B36: Luật người lao động Việt Nam đi làm việc ở nước ngoài theo hợp đồng | C36: QH, CP | D36: TPH | E36: TB | F36: 1034 | G36: 84 | H36: 13x19 | I36: 13000 | J36: PL | K36: 1/2011 | L36: Nhà in Sự Thật
A37: 35 | B37: Bàn về phương pháp giảng dạy bậc đại học (Tài liệu tham khảo phục vụ việc giảng dạy đối với giảng viên Học viện Chính sách và Phát triển) | C37: Học viện Chính sách và Phát triển, PGS, TS. Ngô Doãn Vịnh | D37: TPH | E37: TB | F37: 534 | G37: 120 | H37: 10x15 | I37: 20000 | J37: KT | K37: 1/2011 | L37: Nhà in Sự Thật | M37: BCT (1-4/3/11)
A38: 36 | B38: Vận dụng và phát triển chủ nghĩa Mác - Lênin của Hồ Chí Minh và Đảng ta (Thời kỳ trước đổi mới) | C38: HVCT - HCQG TP HCM, PGS, TS. Bùi Đình Phong, PGS, TS. Phạm Ngọc Anh (Đồng chủ biên) | D38: TPH | E38: 1 | F38: 500 | G38: 568 | H38: 15x22 | I38: 94000 | J38: KĐLL | K38: 1/2011 | L38: Nhà in Sự Thật
A39: 37 | B39: Lịch sử Đảng bộ và nhân dân xã Vĩnh Kim (1930 - 2011) | C39: Huyện uỷ Vĩnh Linh, BCHĐB xã Vĩnh Kim | D39: LKTG | E39: 1 | F39: 250 | G39: 272 | H39: 14,5x20,5 | I39: 0 | J39: QT | K39: 1/2011 | L39: Cty Thông kê và sản xuất bao bì Huế
A40: 38 | B40: Xử lý tình huống công tác Đảng giai đoạn hiện nay | C40: HVCTHCQGTPHCM - TS. Ngô Huy Tiếp, TS. Đinh Ngọc Giang (Đồng chủ biên) | D40: TPH | E40: 1 | F40: 860 | G40: 520 | H40: 14,5x20,5 | I40: 78000 | J40: TPHCM | K40: 1/2011 | L40: Cty TNHH một thành viên in báo nhân dân
...

Sheet 2012
A2: TT | B2: Tên sách | C2: Tác giả | D2: Phương thức | E2: Lần xuất bản | F2: SL in | G2: Trang | H2: Khổ | I2: Giá bìa | J2: BBT | K2: QĐXB | L2: Nơi in | M2: Ghi chú
A3: 1 | B3: Luật cơ yếu | C3: QH | D3: TPH | E3: 1 | F3: 3200 | G3: 32 | H3: 13x19 | I3: 8000 | J3: PL | K3: 1/2012 | L3: In Giao thông | M3: BC tuần (16 đến 20/1/2012): 9 cuốn
A4: 2 | B4: Các văn bản thực hiện Nghị quyết Đại hội đại biểu Đảng bộ huyện Đan Phượng lần thứ XXII, nhiệm kỳ 2010-2015 | C4: Ban Chấp hành Đảng bộ huyện Đan Phượng | D4: LKTG | E4: 1 | F4: 330 | G4: 216 | H4: 13x19 | I4: 0 | J4: TT NCKH | K4: 1/2012 | L4: Nhà in Sự thật
A5: 3 | B5: Công tác giám sát góp phần ngăn ngừa nguy cơ của Đảng cầm quyền | C5: Tập thể tác giả | D5: TPH | E5: 1 | F5: 500 | G5: 404 | H5: 14,5x20,5 | I5: 65000 | J5: SGK | K5: 1/2012 | L5: Nhà in Sự thật
A6: 4 | B6: Ngoại giao Việt Nam- Góc nhìn và suy ngẫm (Sách tham khảo) | C6: Nguyễn Khắc Huỳnh | D6: TPH | E6: 1 | F6: 800 | G6: 288 | H6: 14,5x20,5 | I6: 48000 | J6: QT | K6: 1/2012 | L6: Nhà in Sự thật
A7: 5 | B7: Phát huy vai trò của các tổ chức xã hội ở VN | C7: TS.Thang Văn Phúc, PGS, TS. Nguyễn Minh Phương (Đồng chủ biên) | D7: TPH | E7: 1 | F7: 600 | G7: 420 | H7: 14,5x20,5 | I7: 67000 | J7: SGK | K7: 1/2012 | L7: Nhà in Sự thật
A8: 6 | B8: Tác động của dư luận xã hội đối với ý thức pháp luật của đội ngũ cán bộ cấp cơ sở | C8: TS. Ngọ Văn Nhân | D8: TPH | E8: 1 | F8: 800 | G8: 380 | H8: 14,5x20,5 | I8: 61000 | J8: KĐLL | K8: 1/2012 | L8: Nhà in Sự thật
A9: 7 | B9: Đại biểu Quốc hội khóa XIII (2011-2016) | C9: Quốc hội nước CHXHCN VN | D9: LKTG | E9: 1 | F9: 1700 | G9: 256 | H9: 15x22 | I9: 0 | J9: KT | K9: 1/2012 | L9: In Ngọc Châu
A10: 8 | B10: Giá trị tinh thần truyền thống của dân tộc Việt Nam | C10: GS, NGND Trần Văn Giàu | D10: TWĐH+TPH | E10: 1 | F10: 1000 | G10: 476 | H10: 15x22 | I10: 0 | J10: CN tp HCM | K10: 1/2012 | L10: Cty In báo ND TP HCM
A11: 9 | B11: Văn kiện Quốc hội Toàn tập, tập 8 (1992-1997), quyển 2 (1994-1995) | C11: QH | D11: LKTG | E11: 1 | F11: 1600 | G11: 1400 | H11: 16x24 | I11: 0 | J11: PL | K11: 1/2012 | L11: Cty in Tiến bộ
A12: 10 | B12: Quy định pháp luật về xử phạt vi phạm hành chính về thuốc, mỹ phẩm, trang thiết bị y tế, khám bệnh, chữa bệnh | C12: QH | D12: TPH | F12: 600 | G12: 200 | H12: 13x19 | I12: 29000 | J12: PL | K12: 2/2012 | L12: Nhà in Sự thật | M12: BC tuần (30/1 đến 3/2/2012): 9 cuốn
A13: 11 | B13: Chuyện kể về một thời (Hồi ký) | C13: Lê Hữu Thăng | D13: LKTG | E13: 1 | F13: 1500 | G13: 336 | H13: 13,5x20,5 | I13: 85000 | J13: KĐLL | K13: 2/2012 | L13: In Truyền thông VN
A14: 12 | B14: Câu hỏi và trả lời về môn Thể chế chính trị thế giới đương đại (Sách tham khảo) | C14: TS. Nguyễn Thị Phượng | D14: TPH | F14: 700 | G14: 300 | H14: 14,5x20,5 | I14: 50000 | J14: PL | K14: 2/2012 | L14: Nhà in Sự thật
A15: 13 | B15: Lịch sử Đảng bộ và nhân dân xã Tây Kỳ (1930-2010) | C15: Ban Chấp hành Đảng bộ xã Tây Kỳ | D15: LKTG | E15: 1 | F15: 300 | G15: 400 | H15: 14,5x20,5 | I15: 0 | J15: TT PH | K15: 2/2012 | L15: Nhà in Sự thật
A16: 14 | B16: Luật khám bệnh, chữa bệnh năm 2009 và văn bản hướng dẫn thi hành | C16: QH | D16: TPH | F16: 1400 | G16: 488 | H16: 14,5x20,5 | I16: 73000 | J16: PL | K16: 2/2012 | L16: Nhà in Sự thật
A17: 15 | B17: Dịch vụ logistics ở Việt Nam trong tiến trình hội nhập quốc tế (Sách chuyên khảo) | C17: Trường đại học Kinh tế quốc dân, Viện nghiên cứu Kinh tế và Phát triển, GS, TS, NGƯT Đặng Đình Đào - TS. Nguyễn Minh Sơn (Đồng chủ biên) | D17: LKTG | E17: 1 | F17: 500 | G17: 508 | H17: 14,5x20,5 | I17: 115000 | J17: Đảng | K17: 2/2012 | L17: Cty CP in HN
A18: 16 | B18: Kỷ yếu hoạt động của Đoàn đại biểu Quốc hội tỉnh Lạng Sơn khóa XI, XII | C18: Quốc hội nước CHXHCNVN, Đoàn đại biểu Quốc hội tỉnh Lạng Sơn | D18: LKTG | E18: 1 | F18: 300 | G18: 448 | H18: 14,5x20,5 | I18: 0 | J18: KT | K18: 2/2012 | L18: In Ngọc Châu
A19: 17 | B19: Lịch sử Đảng bộ huyện Thanh Trì (1930-2010) | C19: Đảng bộ Thành phố Hà Nội, Ban Chấp hành Đảng bộ huyện Thanh Trì | D19: LKTG | E19: 1 | F19: 1000 | G19: 516 | H19: 15,5x23,5 | I19: 0 | J19: Đảng | K19: 2/2012 | L19: In Truyền thông VN
A20: 18 | B20: Ban Chỉ đạo và Văn phòng Ban Chỉ đạo Trung ương về phòng, chống tham nhũng (2006-2011) | C20: Văn phòng Ban Chỉ đạo Trung ương về phòng, chống tham nhũng | D20: LKTG | E20: 1 | F20: 700 | G20: 392 | H20: 20x28 | I20: 0 | J20: TT NCKH | K20: 2/2012 | L20: In và VHP
A21: 19 | B21: Lịch sử ngành Dầu khí VN (Đến năm 2010), tập I | C21: Tập đoàn Dầu khí VN | D21: LKTG | E21: 1 | F21: 5000 | G21: 450 | H21: 19x27 | I21: 0 | J21: KT | K21: 2/2012 | L21: Cty TNHH MTV In báo Nhân dân | M21: BC tuần (6 đến 10/2/2012): 7 cuốn
A22: 20 | B22: Lịch sử ngành Dầu khí VN (Đến năm 2010), tập II | C22: Tập đoàn Dầu khí VN | D22: LKTG | E22: 1 | F22: 5000 | G22: 684 | H22: 19x27 | I22: 0 | J22: KT | K22: 2/2012 | L22: Cty TNHH MTV In báo Nhân dân
A23: 21 | B23: Lịch sử ngành Dầu khí VN (Đến năm 2010), tập III | C23: Tập đoàn Dầu khí VN | D23: LKTG | E23: 1 | F23: 5000 | G23: 592 | H23: 19x27 | I23: 0 | J23: KT | K23: 2/2012 | L23: Cty TNHH MTV In báo Nhân dân
A24: 22 | B24: Văn bản của Ban Chấp hành Trung ương, Bộ Chính trị, Ban Bí thư và Ủy ban Kiểm tra Trung ương về công tác kiểm tra, giám sát và kỷ luật của Đảng | C24: Ủy ban Kiểm tra Trung ương | D24: TPH | E24: 1 | F24: 25038 | G24: 352 | H24: 13x19 | I24: 47000 | J24: SGK | K24: 2/2012 | L24: Cty in Tiến bộ
A25: 23 | B25: Một số vấn đề chính trị quốc tế trong giai đoạn hiện nay | C25: PGS, TS. Ng. Hoàng Giáp (Chủ biên), PGS, TS. Ng. Thị Quế, PGS, TS. Thái Văn Long, PGS, TS. Phan Văn Rân | D25: TPH | E25: 1 | F25: 500 | G25: 304 | H25: 14,5x20,5 | I25: 51000 | J25: Đảng | K25: 2/2012 | L25: Nhà in Sự thật
A26: 24 | B26: Phát triển đồng bộ và tương xứng văn hóa với kinh tế | C26: Viện nghiên cứu Phát triển thành phố Hồ Chí Minh, TS. Hồ Bá Thâm (Chủ biên) | D26: TPH | E26: 1 | F26: 500 | G26: 360 | H26: 14,5x20,5 | I26: 71000 | J26: CN tp HCM | K26: 2/2012 | L26: Cty In báo ND TP HCM
A27: 25 | B27: Phong trào chấn hưng Phật giáo ở miền Bắc Việt Nam (1924-1954) | C27: Lê Tâm Đắc | D27: TPH | E27: 1 | F27: 500 | G27: 304 | H27: 14,5x20,5 | I27: 51000 | J27: Đảng | K27: 2/2012 | L27: Nhà in Sự thật
A28: 26 | B28: Truyền thông- lý thuyết và kỹ năng cơ bản | C28: Học viện Báo chí và Tuyên truyền, PGS, TS. Ng. Văn Dững (Chủ biên), TS. Đỗ Thị Thu Hằng | D28: TPH | E28: TB | F28: 1550 | G28: 315 | H28: 14,5x20,5 | I28: 52000 | J28: QT | K28: 2/2012 | L28: In và TM Thuận Phát
A29: 27 | B29: Lịch sử Đảng bộ và nhân dân xã Trung Hải (1930-2010) | C29: Ban Chấp hành Đảng bộ xã Trung Hải | D29: LKTG | E29: 1 | F29: 400 | G29: 456 | H29: 14,5x20,5 | I29: 0 | J29: Đảng | K29: 2/2012 | L29: In Truyền thông VN
A30: 28 | B30: Quy định xử phạt vi phạm hành chính trong lĩnh vực giao thông đường thủy nội địa | C30: QH | D30: TPH | E30: 1 | F30: 700 | G30: 160 | H30: 13x19 | I30: 25000 | J30: PL | K30: 2/2012 | L30: Nhà in Sự thật | M30: BC tuần (13 đến 17/2/2012): 6 cuốn
